Workbook

Sheet PLJ01
C3: Loja 01 | U3: 2025 | X3: Açougue
U4: Janeiro | V4: ='Hist LJ01'!B20 -> 4672168.2 | X4: Venda Ano 2025 | Y4: =SUMIFS('Hist LJ01'!$N:$N,'Hist LJ01'!$P:$P,"Açougue") -> 11128757
C5: Venda 2025 | E5: Venda R$ Funcionarios | H5: Gerente | P5: Abertura da loja | U5: Fevereiro | V5: ='Hist LJ01'!C20 -> 4395175.2 | X5: Media mês | Y5: =Y4/12 -> 927396.42
C6: =V16 -> 59946140 | E6: 43000 | U6: Março | V6: ='Hist LJ01'!D20 -> 5003146.9 | X6: Venda Por QL | Y6: =Y5/H35 -> 71338.186
H7: 1 | U7: Abril | V7: ='Hist LJ01'!E20 -> 5068465.7 | X7: Meta | Y7: 75000
C8: Media 12 mêses | E8: Proposta Quant | P8: Seg a Sab | R8: Domingos | U8: Maio | V8: ='Hist LJ01'!F20 -> 5058912.5
C9: =C6/12 -> 4995511.7 | E9: =C9/E6 -> 116.17469 | H9: Subgerente | P9: 08:00 as 21:00 | R9: 08:00 as 20:00 | U9: Junho | V9: ='Hist LJ01'!G20 -> 4808087.7 | X9: Hortifrut
U10: Julho | V10: ='Hist LJ01'!H20 -> 5011604.6 | X10: Venda Ano 2025 | Y10: =SUMIFS('Hist LJ01'!$N:$N,'Hist LJ01'!$P:$P,"Hortifruti") -> 7890617.3
H11: 2 | U11: Agosto | V11: ='Hist LJ01'!I20 -> 5020870.9 | X11: Media mês | Y11: =Y10/12 -> 657551.44
U12: Setembro | V12: ='Hist LJ01'!J20 -> 4777027.7 | X12: Venda Por QL | Y12: =Y11/J35 -> 93935.92
C13: FRENTE CAIXA | E13: LOJA | H13: AÇOUGUE | J13: HORTFRUTI | L13: FRIOS | N13: PADARIA | O13: CONFEITARIA | P13: ROTISSERIA | R13: Depósito | U13: Outubro | V13: ='Hist LJ01'!K20 -> 5009122.2 | X13: Meta | Y13: 80000
C14: Encarregado | E14: Encarregado | H14: Encarregado | J14: Encarregado | L14: Encarregado | N14: Encarregado | O14: Encarregado | P14: Encarregado | R14: Encarregado | U14: Novembro | V14: ='Hist LJ01'!L20 -> 5078982.2
C15: 1 | E15: 1 | H15: 1 | J15: 1 | L15: 1 | N15: 1 | O15: 0 | P15: 0 | R15: 1 | U15: Dezenbro | V15: ='Hist LJ01'!M20 -> 6042576.6 | X15: Confeitaria
U16: Total | V16: ='Hist LJ01'!N20 -> 59946140 | X16: Venda Ano 2025 | Y16: =SUMIFS('Hist LJ01'!$N:$N,'Hist LJ01'!$P:$P,"Confeitaria") -> 1377199.1
C17: Fiscal de Caixa | E17: Repositor | F17: Limpeza | H17: Desossador | J17: Repositor | L17: Atendente | N17: Atendente | O17: Confeiteira | P17: Cozinheiro | R17: Conferente | U17: Media 12 meses | V17: =V16/12 -> 4995511.7 | X17: Media mês | Y17: =Y16/12 -> 114766.59
C18: 5 | E18: 9 | F18: 3 | H18: 2 | J18: 8 | L18: 4 | N18: 5 | O18: 2 | P18: 2 | R18: 1 | U18: Media por QL | V18: =V17/43000 -> 116.17469 | X18: Venda Por QL | Y18: =Y17/O35 -> 38255.53
X19: Meta | Y19: 26000
C20: Operador Caixa | E20: Cartazista | F20: Estacionamento | H20: Açogueiro | J20: Rep Cortes | L20: Repositor | N20: Padeiro | O20: Auxiliar | P20: Auxiliar | R20: Auxiliar
C21: 22 | E21: 1 | F21: 2 | H21: 5 | J21: 0 | L21: 2 | N21: 3 | O21: 1 | P21: 1 | R21: 3 | U21: Frios / Congelados / Laticinios / Peix | X21: Padaria
U22: Venda Ano 2025 | V22: =SUMIFS('Hist LJ01'!$N:$N,'Hist LJ01'!$P:$P,"Frios") -> 6438152.4 | X22: Venda Ano 2025 | Y22: =SUMIFS('Hist LJ01'!$N:$N,'Hist LJ01'!$P:$P,"Padaria") -> 2731772.5
C23: Empacotador | E23: Auxiliar | F23: Entregador | H23: Balconista | N23: Auxiliar | R23: Controladoria | U23: Media mês | V23: =V22/12 -> 536512.7 | X23: Media mês | Y23: =Y22/12 -> 227647.71
C24: 4 | E24: 1 | F24: 2 | H24: 5 | N24: 3 | R24: 2 | U24: Venda Por QL | V24: =V23/L35 -> 107302.54 | X24: Venda Por QL | Y24: =Y23/N35 -> 18970.643
U25: Meta | V25: 80000 | X25: Meta | Y25: 16000
E26: Aprendiz | F26: E-Commerce | R26: Prevenção
E27: 6 | F27: 0 | R27: 1 | U27: Loja Total | X27: Rotisseria
U28: Venda Ano 2025 | V28: =SUMIFS('Hist LJ01'!$N:$N,'Hist LJ01'!$P:$P,"Loja") -> 29221061 | X28: Venda Ano 2025 | Y28: =SUMIFS('Hist LJ01'!$N:$N,'Hist LJ01'!$P:$P,"Rotisseria") -> 1158581
E29: Gestão Pessoas | F29: Cor. Bancário | U29: Media mês | V29: =V28/12 -> 2435088.4 | X29: Media mês | Y29: =Y28/12 -> 96548.417
E30: 1 | F30: 0 | U30: Venda Por QL | V30: =V29/(E35+R35) -> 65813.201 | X30: Venda Por QL | Y30: =Y29/P35 -> 32182.806
C31: Orçado Acima | U31: Meta | V31: 160000 | X31: Meta | Y31: 25000
C32: Total | E32: Total | H32: Total | J32: Total | L32: Total | N32: PADARIA | O32: CONFEITARIA | P32: ROTISSERIA | R32: Total
C33: =C30+C27+C24+C21+C18+C15 -> 32 | E33: =E30+E27+E24+E21+E18+E15+F18+F21+F24+F27+F30 -> 26 | H33: =H30+H27+H24+H21+H18+H15 -> 13 | J33: =J30+J27+J24+J21+J18+J15 -> 9 | L33: =L30+L27+L24+L21+L18+L15 -> 7 | N33: =N30+N27+N24+N21+N18+N15 -> 12 | O33: =O30+O27+O24+O21+O18+O15 -> 3 | P33: =P30+P27+P24+P21+P18+P15 -> 3 | R33: =R15+R18+R21+R24+R27 -> 8 | U33: Frente Caixa | X33: Prod Alimentos
C34: Total | E34: Total | H34: Total | J34: Total | L34: Total | N34: PADARIA | O34: CONFEITARIA | P34: ROTISSERIA | R34: Total | U34: Venda Ano 2025 | V34: =SUMIFS('Hist LJ01'!$N:$N,'Hist LJ01'!$P:$P,"Loja") -> 29221061 | X34: Venda Ano 2025 | Y34: =Y28+Y22+Y16 -> 5267552.6
C35: 29 | E35: 31 | H35: 13 | J35: 7 | L35: 5 | N35: 12 | O35: 3 | P35: 3 | R35: 6 | U35: Media mês | V35: =V34/12 -> 2435088.4 | X35: Media mês | Y35: =Y34/12 -> 438962.72
C36: Real Fev/26 | U36: Venda Por QL | V36: =V35/C35 -> 83968.567 | X36: Venda Por QL | Y36: =Y35/SUM(N35:P35) -> 24386.818
J37: Total | L37: Real | N37: Diferença | U37: Meta | V37: 138000 | X37: Meta | Y37: 21000
J39: =SUM(C33:R33)+H11+H7 -> 116 | L39: =SUM(A35:S35) -> 109 | N39: =L39-J39 -> -7

Sheet PLJ02
C3: Loja 02 | U3: 2025 | X3: Açougue
U4: Janeiro | V4: ='Hist LJ02'!B20 -> 2839277.9 | X4: Venda Ano 2025 | Y4: =SUMIFS('Hist LJ02'!$N:$N,'Hist LJ02'!$P:$P,"Açougue") -> 5818951.9
C5: Venda 2025 | E5: Venda R$ Funcionarios | H5: Gerente | P5: Abertura da loja | U5: Fevereiro | V5: ='Hist LJ02'!C20 -> 2702365.5 | X5: Media mês | Y5: =Y4/12 -> 484912.66
C6: =V16 -> 35741919 | E6: 43000 | U6: Março | V6: ='Hist LJ02'!D20 -> 3066044.8 | X6: Venda Por QL | Y6: =Y5/H35 -> 80818.777
H7: 1 | U7: Abril | V7: ='Hist LJ02'!E20 -> 3202572.4 | X7: Meta | Y7: 75000
C8: Media 12 mêses | E8: Proposta Quant | P8: Seg a Sab | R8: Domingos | U8: Maio | V8: ='Hist LJ02'!F20 -> 3090885
C9: =C6/12 -> 2978493.2 | E9: =C9/E6 -> 69.267285 | H9: Subgerente | P9: 08:00 as 21:00 | R9: 08:00 as 20:00 | U9: Junho | V9: ='Hist LJ02'!G20 -> 2939070.2 | X9: Hortifrut
U10: Julho | V10: ='Hist LJ02'!H20 -> 3107973 | X10: Venda Ano 2025 | Y10: =SUMIFS('Hist LJ02'!$N:$N,'Hist LJ02'!$P:$P,"Hortifruti") -> 5368221.2
H11: 1 | U11: Agosto | V11: ='Hist LJ02'!I20 -> 3033801.9 | X11: Media mês | Y11: =Y10/12 -> 447351.77
U12: Setembro | V12: ='Hist LJ02'!J20 -> 2801352.7 | X12: Venda Por QL | Y12: =Y11/J35 -> 89470.353
C13: FRENTE CAIXA | E13: LOJA | H13: AÇOUGUE | J13: HORTFRUTI | L13: FRIOS | N13: PADARIA | O13: CONFEITARIA | P13: ROTISSERIA | R13: Depósito | U13: Outubro | V13: ='Hist LJ02'!K20 -> 2892700.9 | X13: Meta | Y13: 80000
C14: Encarregado | E14: Encarregado | H14: Encarregado | J14: Encarregado | L14: Encarregado | N14: Encarregado | O14: Encarregado | P14: Encarregado | R14: Encarregado | U14: Novembro | V14: ='Hist LJ02'!L20 -> 2797129.7
C15: 1 | E15: 1 | H15: 1 | J15: 1 | L15: 1 | N15: 1 | O15: 0 | P15: 0 | R15: 1 | U15: Dezenbro | V15: ='Hist LJ02'!M20 -> 3268745 | X15: Confeitaria
U16: Total | V16: ='Hist LJ02'!N20 -> 35741919 | X16: Venda Ano 2025 | Y16: =SUMIFS('Hist LJ02'!$N:$N,'Hist LJ02'!$P:$P,"Confeitaria") -> 576209.63
C17: Fiscal de Caixa | E17: Repositor | F17: Limpeza | H17: Desossador | J17: Repositor | L17: Atendente | N17: Atendente | O17: Confeiteira | P17: Cozinheiro | R17: Conferente | U17: Media 12 meses | V17: =V16/12 -> 2978493.2 | X17: Media mês | Y17: =Y16/12 -> 48017.469
C18: 3 | E18: 5 | F18: 2 | H18: 1 | J18: 4 | L18: 2 | N18: 3 | O18: 1 | P18: 1 | R18: 1 | U18: Media por QL | V18: =V17/43000 -> 69.267285 | X18: Venda Por QL | Y18: =Y17/O35 -> 24008.735
X19: Meta | Y19: 26000
C20: Operador Caixa | E20: Cartazista | F20: Estacionamento | H20: Açogueiro | J20: Rep Cortes | L20: Repositor | N20: Padeiro | O20: Auxiliar | P20: Auxiliar | R20: Auxiliar
C21: 11 | E21: 1 | F21: 1 | H21: 3 | J21: 1 | L21: 1 | N21: 2 | O21: 1 | P21: 0 | R21: 1 | U21: Frios / Congelados / Laticinios / Peix | X21: Padaria
U22: Venda Ano 2025 | V22: =SUMIFS('Hist LJ02'!$N:$N,'Hist LJ02'!$P:$P,"Frios") -> 4618335.4 | X22: Venda Ano 2025 | Y22: =SUMIFS('Hist LJ02'!$N:$N,'Hist LJ02'!$P:$P,"Padaria") -> 1697669
C23: Empacotador | E23: Auxiliar | F23: Entregador | H23: Balconista | N23: Auxiliar | R23: Controladoria | U23: Media mês | V23: =V22/12 -> 384861.29 | X23: Media mês | Y23: =Y22/12 -> 141472.42
C24: 1 | E24: 0 | F24: 1 | H24: 2 | N24: 1 | R24: 1 | U24: Venda Por QL | V24: =V23/L35 -> 96215.321 | X24: Venda Por QL | Y24: =Y23/N35 -> 15719.157
U25: Meta | V25: 80000 | X25: Meta | Y25: 16000
E26: Aprendiz | F26: E-Commerce | R26: Prevenção
E27: 7 | F27: 1 | R27: 1 | U27: Loja Total | X27: Rotisseria
U28: Venda Ano 2025 | V28: =SUMIFS('Hist LJ02'!$N:$N,'Hist LJ02'!$P:$P,"Loja") -> 17272292 | X28: Venda Ano 2025 | Y28: =SUMIFS('Hist LJ02'!$N:$N,'Hist LJ02'!$P:$P,"Rotisseria") -> 390239.68
E29: Gestão Pessoas | F29: Cor. Bancário | U29: Media mês | V29: =V28/12 -> 1439357.7 | X29: Media mês | Y29: =Y28/12 -> 32519.973
E30: 0 | F30: 0 | U30: Venda Por QL | V30: =V29/(E35+R35) -> 59973.236 | X30: Venda Por QL | Y30: =Y29/P35 -> 32519.973
C31: Orçado Acima | U31: Meta | V31: 160000 | X31: Meta | Y31: 25000
C32: Total | E32: Total | H32: Total | J32: Total | L32: Total | N32: PADARIA | O32: CONFEITARIA | P32: ROTISSERIA | R32: Total
C33: =C30+C27+C24+C21+C18+C15 -> 16 | E33: =E30+E27+E24+E21+E18+E15+F18+F21+F24+F27+F30 -> 19 | H33: =H30+H27+H24+H21+H18+H15 -> 7 | J33: =J30+J27+J24+J21+J18+J15 -> 6 | L33: =L30+L27+L24+L21+L18+L15 -> 4 | N33: =N30+N27+N24+N21+N18+N15 -> 7 | O33: =O30+O27+O24+O21+O18+O15 -> 2 | P33: =P30+P27+P24+P21+P18+P15 -> 1 | R33: =R15+R18+R21+R24+R27+R30 -> 5 | U33: Frente Caixa | X33: Prod Alimentos
C34: Total | E34: Total | H34: Total | J34: Total | L34: Total | N34: PADARIA | O34: CONFEITARIA | P34: ROTISSERIA | R34: Total | U34: Venda Ano 2025 | V34: =SUMIFS('Hist LJ02'!$N:$N,'Hist LJ02'!$P:$P,"Loja") -> 17272292 | X34: Venda Ano 2025 | Y34: =Y28+Y22+Y16 -> 2664118.3
C35: 20 | E35: 22 | H35: 6 | J35: 5 | L35: 4 | N35: 9 | O35: 2 | P35: 1 | R35: 2 | U35: Media mês | V35: =V34/12 -> 1439357.7 | X35: Media mês | Y35: =Y34/12 -> 222009.86
C36: Real Fev/26 | U36: Venda Por QL | V36: =V35/C35 -> 71967.884 | X36: Venda Por QL | Y36: =Y35/SUM(N35:P35) -> 18500.822
J37: Total | L37: Real | N37: Diferença | U37: Meta | V37: 138000 | X37: Meta | Y37: 21000
J39: =SUM(C33:R33)+H11+H7 -> 69 | L39: =SUM(A35:S35) -> 71 | N39: =L39-J39 -> 2

Sheet PLJ03
C3: Loja 03 | U3: 2025 | X3: Açougue
U4: Janeiro | V4: ='Hist LJ03'!B20 -> 2785692.2 | X4: Venda Ano 2025 | Y4: =SUMIFS('Hist LJ03'!$N:$N,'Hist LJ03'!$P:$P,"Açougue") -> 6362337.4
C5: Venda 2025 | E5: Venda R$ Funcionarios | H5: Gerente | P5: Abertura da loja | U5: Fevereiro | V5: ='Hist LJ03'!C20 -> 2655535.3 | X5: Media mês | Y5: =Y4/12 -> 530194.78
C6: =V16 -> 35305398 | E6: 43000 | U6: Março | V6: ='Hist LJ03'!D20 -> 3046525.3 | X6: Venda Por QL | Y6: =Y5/H35 -> 75742.112
H7: 1 | U7: Abril | V7: ='Hist LJ03'!E20 -> 2909466.9 | X7: Meta | Y7: 75000
C8: Media 12 mêses | E8: Proposta Quant | P8: Seg a Sab | R8: Domingos | U8: Maio | V8: ='Hist LJ03'!F20 -> 3015715.3
C9: =C6/12 -> 2942116.5 | E9: =C9/E6 -> 68.421314 | H9: Subgerente | P9: 08:00 as 21:00 | R9: 08:00 as 20:00 | U9: Junho | V9: ='Hist LJ03'!G20 -> 2860012.5 | X9: Hortifrut
U10: Julho | V10: ='Hist LJ03'!H20 -> 2892461.7 | X10: Venda Ano 2025 | Y10: =SUMIFS('Hist LJ03'!$N:$N,'Hist LJ03'!$P:$P,"Hortifruti") -> 4209707.6
H11: 1 | U11: Agosto | V11: ='Hist LJ03'!I20 -> 2995538 | X11: Media mês | Y11: =Y10/12 -> 350808.97
U12: Setembro | V12: ='Hist LJ03'!J20 -> 2852898.7 | X12: Venda Por QL | Y12: =Y11/J35 -> 70161.793
C13: FRENTE CAIXA | E13: LOJA | H13: AÇOUGUE | J13: HORTFRUTI | L13: FRIOS | N13: PADARIA | O13: CONFEITARIA | P13: ROTISSERIA | R13: Depósito | U13: Outubro | V13: ='Hist LJ03'!K20 -> 2900315.7 | X13: Meta | Y13: 80000
C14: Encarregado | E14: Encarregado | H14: Encarregado | J14: Encarregado | L14: Encarregado | N14: Encarregado | O14: Encarregado | P14: Encarregado | R14: Encarregado | U14: Novembro | V14: ='Hist LJ03'!L20 -> 2981089.7
C15: 1 | E15: 1 | H15: 1 | J15: 1 | L15: 1 | N15: 1 | O15: 0 | P15: 0 | R15: 1 | U15: Dezenbro | V15: ='Hist LJ03'!M20 -> 3410146.5 | X15: Confeitaria
U16: Total | V16: ='Hist LJ03'!N20 -> 35305398 | X16: Venda Ano 2025 | Y16: =SUMIFS('Hist LJ03'!$N:$N,'Hist LJ03'!$P:$P,"Confeitaria") -> 410726.58
C17: Fiscal de Caixa | E17: Repositor | F17: Limpeza | H17: Desossador | J17: Repositor | L17: Atendente | N17: Atendente | O17: Confeiteira | P17: Forneiro | R17: Conferente | U17: Media 12 meses | V17: =V16/12 -> 2942116.5 | X17: Media mês | Y17: =Y16/12 -> 34227.215
C18: 3 | E18: 6 | F18: 2 | H18: 1 | J18: 3 | L18: 2 | N18: 1 | O18: 1 | P18: 1 | R18: 1 | U18: Media por QL | V18: =V17/43000 -> 68.421314 | X18: Venda Por QL | Y18: =Y17/O35 -> 17113.607
X19: Meta | Y19: 26000
C20: Operador Caixa | E20: Cartazista | F20: Estacionamento | H20: Açogueiro | J20: Rep Cortes | L20: Repositor | N20: Padeiro | O20: Auxiliar | P20: Auxiliar | R20: Auxiliar
C21: 19 | E21: 1 | F21: 0 | H21: 4 | J21: 1 | L21: 1 | N21: 0 | O21: 1 | P21: 0 | R21: 1 | U21: Frios / Congelados / Laticinios / Peix | X21: Padaria
U22: Venda Ano 2025 | V22: =SUMIFS('Hist LJ03'!$N:$N,'Hist LJ03'!$P:$P,"Frios") -> 3697699.6 | X22: Venda Ano 2025 | Y22: =SUMIFS('Hist LJ03'!$N:$N,'Hist LJ03'!$P:$P,"Padaria") -> 815953.92
C23: Empacotador | E23: Auxiliar | F23: Entregador | H23: Balconista | N23: Auxiliar | R23: Controladoria | U23: Media mês | V23: =V22/12 -> 308141.63 | X23: Media mês | Y23: =Y22/12 -> 67996.16
C24: 1 | E24: 0 | F24: 1 | H24: 2 | N24: 1 | R24: 1 | U24: Venda Por QL | V24: =V23/L35 -> 102713.88 | X24: Venda Por QL | Y24: =Y23/N35 -> 16999.04
U25: Meta | V25: 80000 | X25: Meta | Y25: 16000
E26: Aprendiz | F26: E-Commerce | R26: Prevenção
E27: 2 | F27: 0 | R27: 1 | U27: Loja Total | X27: Rotisseria
U28: Venda Ano 2025 | V28: =SUMIFS('Hist LJ03'!$N:$N,'Hist LJ03'!$P:$P,"Loja") -> 19806359 | X28: Venda Ano 2025 | Y28: =SUMIFS('Hist LJ03'!$N:$N,'Hist LJ03'!$P:$P,"Rotisseria") -> 2613.68
E29: Gestão Pessoas | F29: Cor. Bancário | U29: Media mês | V29: =V28/12 -> 1650529.9 | X29: Media mês | Y29: =Y28/12 -> 217.80667
E30: 0 | F30: 1 | U30: Venda Por QL | V30: =V29/(E35+R35) -> 97089.996 | X30: Venda Por QL | Y30: =IFERROR(Y29/P35,0) -> 0
C31: Orçado Acima | U31: Meta | V31: 160000 | X31: Meta | Y31: 25000
C32: Total | E32: Total | H32: Total | J32: Total | L32: Total | N32: PADARIA | O32: CONFEITARIA | P32: ROTISSERIA | R32: Total
C33: =C30+C27+C24+C21+C18+C15 -> 24 | E33: =E30+E27+E24+E21+E18+E15+F30+F27+F24+F21+F18 -> 14 | H33: =H30+H27+H24+H21+H18+H15 -> 8 | J33: =J30+J27+J24+J21+J18+J15 -> 5 | L33: =L30+L27+L24+L21+L18+L15 -> 4 | N33: =N30+N27+N24+N21+N18+N15 -> 3 | O33: =O30+O27+O24+O21+O18+O15 -> 2 | P33: =P30+P27+P24+P21+P18+P15 -> 1 | R33: =R27+R24+R21+R18+R15 -> 5 | U33: Frente Caixa | X33: Prod Alimentos
C34: Total | E34: Total | H34: Total | J34: Total | L34: Total | N34: PADARIA | O34: CONFEITARIA | P34: ROTISSERIA | R34: Total | U34: Venda Ano 2025 | V34: =SUMIFS('Hist LJ03'!$N:$N,'Hist LJ03'!$P:$P,"Loja") -> 19806359 | X34: Venda Ano 2025 | Y34: =Y28+Y22+Y16 -> 1229294.2
C35: 22 | E35: 15 | H35: 7 | J35: 5 | L35: 3 | N35: 4 | O35: 2 | P35: =P33/SUM($N$33:$P$33)*$O$36 -> 0 | R35: 2 | U35: Media mês | V35: =V34/12 -> 1650529.9 | X35: Media mês | Y35: =Y34/12 -> 102441.18
C36: Real Fev/26 | U36: Venda Por QL | V36: =V35/C35 -> 75024.088 | X36: Venda Por QL | Y36: =Y35/SUM(N35:P35) -> 17073.53
J37: Total | L37: Real | N37: Diferença | U37: Meta | V37: 138000 | X37: Meta | Y37: 21000
J39: =SUM(C33:R33)+H11+H7 -> 68 | L39: =SUM(C35:R35) -> 60 | N39: =L39-J39 -> -8

Sheet PLJ04
C3: Loja 04 | U3: 2025 | X3: Açougue
U4: Janeiro | V4: ='Hist LJ04'!B20 -> 2255242.1 | X4: Venda Ano 2025 | Y4: =SUMIFS('Hist LJ04'!$N:$N,'Hist LJ04'!$P:$P,"Açougue") -> 5249804.4
C5: Venda 2025 | E5: Venda R$ Funcionarios | H5: Gerente | P5: Abertura da loja | U5: Fevereiro | V5: ='Hist LJ04'!C20 -> 2123168.4 | X5: Media mês | Y5: =Y4/12 -> 437483.7
C6: =V16 -> 28365264 | E6: 43000 | U6: Março | V6: ='Hist LJ04'!D20 -> 2418000.3 | X6: Venda Por QL | Y6: =Y5/H35 -> 72913.95
H7: 1 | U7: Abril | V7: ='Hist LJ04'!E20 -> 2311418.4 | X7: Meta | Y7: 75000
C8: Media 12 mêses | E8: Proposta Quant | P8: Seg a Sab | R8: Domingos | U8: Maio | V8: ='Hist LJ04'!F20 -> 2406334.2
C9: =C6/12 -> 2363772 | E9: =C9/E6 -> 54.971441 | H9: Subgerente | P9: 08:00 as 21:00 | R9: 08:00 as 20:00 | U9: Junho | V9: ='Hist LJ04'!G20 -> 2302464.1 | X9: Hortifrut
U10: Julho | V10: ='Hist LJ04'!H20 -> 2373204.1 | X10: Venda Ano 2025 | Y10: =SUMIFS('Hist LJ04'!$N:$N,'Hist LJ04'!$P:$P,"Hortifruti") -> 4006181.3
H11: 1 | U11: Agosto | V11: ='Hist LJ04'!I20 -> 2392137.9 | X11: Media mês | Y11: =Y10/12 -> 333848.45
U12: Setembro | V12: ='Hist LJ04'!J20 -> 2319689.5 | X12: Venda Por QL | Y12: =Y11/J35 -> 66769.689
C13: FRENTE CAIXA | E13: LOJA | H13: AÇOUGUE | J13: HORTFRUTI | L13: FRIOS | N13: PADARIA | O13: CONFEITARIA | P13: ROTISSERIA | R13: Depósito | U13: Outubro | V13: ='Hist LJ04'!K20 -> 2358183 | X13: Meta | Y13: 80000
C14: Encarregado | E14: Encarregado | H14: Encarregado | J14: Encarregado | L14: Encarregado | N14: Encarregado | O14: Encarregado | P14: Encarregado | R14: Encarregado | U14: Novembro | V14: ='Hist LJ04'!L20 -> 2405167.4
C15: 1 | E15: 1 | H15: 1 | J15: 1 | L15: 0 | N15: 0 | O15: 0 | P15: 0 | R15: 0 | U15: Dezenbro | V15: ='Hist LJ04'!M20 -> 2700254.2 | X15: Confeitaria
U16: Total | V16: ='Hist LJ04'!N20 -> 28365264 | X16: Venda Ano 2025 | Y16: =SUMIFS('Hist LJ04'!$N:$N,'Hist LJ04'!$P:$P,"Confeitaria") -> 435801.47
C17: Fiscal de Caixa | E17: Repositor | F17: Limpeza | H17: Desossador | J17: Repositor | L17: Atendente | N17: Atendente | O17: Confeiteira | P17: Cozinheiro | R17: Conferente | U17: Media 12 meses | V17: =V16/12 -> 2363772 | X17: Media mês | Y17: =Y16/12 -> 36316.789
C18: 3 | E18: 4 | F18: 2 | H18: 1 | J18: 2 | L18: 0 | N18: 3 | O18: 1 | P18: 0 | R18: 1 | U18: Media por QL | V18: =V17/43000 -> 54.971441 | X18: Venda Por QL | Y18: =Y17/O35 -> 18158.395
X19: Meta | Y19: 26000
C20: Operador Caixa | E20: Cartazista | F20: Estacionamento | H20: Açogueiro | J20: Rep Cortes | L20: Repositor | N20: Padeiro | O20: Auxiliar | P20: Auxiliar | R20: Auxiliar
C21: 12 | E21: 1 | F21: 1 | H21: 2 | J21: 1 | L21: 1 | N21: 1 | O21: 1 | P21: 0 | R21: 1 | U21: Frios / Congelados / Laticinios / Peix | X21: Padaria
U22: Venda Ano 2025 | V22: =SUMIFS('Hist LJ04'!$N:$N,'Hist LJ04'!$P:$P,"Frios") -> 3364237.4 | X22: Venda Ano 2025 | Y22: =SUMIFS('Hist LJ04'!$N:$N,'Hist LJ04'!$P:$P,"Padaria") -> 988989.5
C23: Empacotador | E23: Auxiliar | F23: Entregador | H23: Balconista | N23: Auxiliar | R23: Controladoria | U23: Media mês | V23: =V22/12 -> 280353.12 | X23: Media mês | Y23: =Y22/12 -> 82415.792
C24: 1 | E24: 0 | F24: 1 | H24: 2 | N24: 1 | R24: 1 | U24: Venda Por QL | V24: =V23/L35 -> 280353.12 | X24: Venda Por QL | Y24: =Y23/N35 -> 13735.965
U25: Meta | V25: 80000 | X25: Meta | Y25: 16000
E26: Aprendiz | F26: E-Commerce | R26: Prevenção
E27: 4 | F27: 0 | R27: 1 | U27: Loja Total | X27: Rotisseria
U28: Venda Ano 2025 | V28: =SUMIFS('Hist LJ04'!$N:$N,'Hist LJ04'!$P:$P,"Loja") -> 14295425 | X28: Venda Ano 2025 | Y28: =SUMIFS('Hist LJ04'!$N:$N,'Hist LJ04'!$P:$P,"Rotisseria") -> 24824.36
E29: Gestão Pessoas | F29: Cor. Bancário | U29: Media mês | V29: =V28/12 -> 1191285.4 | X29: Media mês | Y29: =Y28/12 -> 2068.6967
E30: 0 | F30: 0 | U30: Venda Por QL | V30: =V29/(E35+R35) -> 70075.613 | X30: Venda Por QL | Y30: =IFERROR(Y29/P35,0) -> 0
C31: Orçado Acima | U31: Meta | V31: 160000 | X31: Meta | Y31: 25000
C32: Total | E32: Total | H32: Total | J32: Total | L32: Total | N32: PADARIA | O32: CONFEITARIA | P32: ROTISSERIA | R32: Total
C33: =C30+C27+C24+C21+C18+C15 -> 17 | E33: =E30+E27+E24+E21+E18+E15+F30+F27+F24+F21+F18 -> 14 | H33: =H30+H27+H24+H21+H18+H15 -> 6 | J33: =J30+J27+J24+J21+J18+J15 -> 4 | L33: =L30+L27+L24+L21+L18+L15 -> 1 | N33: =N30+N27+N24+N21+N18+N15 -> 5 | O33: =O30+O27+O24+O21+O18+O15 -> 2 | P33: =P30+P27+P24+P21+P18+P15 -> 0 | R33: =R30+R27+R24+R21+R18+R15 -> 4 | U33: Frente Caixa | X33: Prod Alimentos
C34: Total | E34: Total | H34: Total | J34: Total | L34: Total | N34: PADARIA | O34: CONFEITARIA | P34: ROTISSERIA | R34: Total | U34: Venda Ano 2025 | V34: =SUMIFS('Hist LJ04'!$N:$N,'Hist LJ04'!$P:$P,"Loja") -> 14295425 | X34: Venda Ano 2025 | Y34: =Y28+Y22+Y16 -> 1449615.3
C35: 14 | E35: 14 | H35: 6 | J35: 5 | L35: 1 | N35: 6 | O35: 2 | P35: =P33/SUM($N$33:$P$33)*$O$36 -> 0 | R35: 3 | U35: Media mês | V35: =V34/12 -> 1191285.4 | X35: Media mês | Y35: =Y34/12 -> 120801.28
C36: Real Fev/26 | U36: Venda Por QL | V36: =V35/C35 -> 85091.816 | X36: Venda Por QL | Y36: =Y35/SUM(N35:P35) -> 15100.16
J37: Total | L37: Real | N37: Diferença | U37: Meta | V37: 138000 | X37: Meta | Y37: 21000
J39: =SUM(C33:R33)+H11+H7 -> 55 | L39: =SUM(C35:R35) -> 51 | N39: =L39-J39 -> -4

Sheet PLJ05
C3: Loja 05 | U3: 2025 | X3: Açougue
U4: Janeiro | V4: ='Hist LJ05'!B20 -> 3181874.2 | X4: Venda Ano 2025 | Y4: =SUMIFS('Hist LJ05'!$N:$N,'Hist LJ05'!$P:$P,"Açougue") -> 9071357.5
C5: Venda 2025 | E5: Venda R$ Funcionarios | H5: Gerente | P5: Abertura da loja | U5: Fevereiro | V5: ='Hist LJ05'!C20 -> 3138878.8 | X5: Media mês | Y5: =Y4/12 -> 755946.46
C6: =V16 -> 42055414 | E6: 43000 | U6: Março | V6: ='Hist LJ05'!D20 -> 3437306.3 | X6: Venda Por QL | Y6: =Y5/H35 -> 94493.307
H7: 1 | U7: Abril | V7: ='Hist LJ05'!E20 -> 3626851.4 | X7: Meta | Y7: 75000
C8: Media 12 mêses | E8: Proposta Quant | P8: Seg a Sab | R8: Domingos | U8: Maio | V8: ='Hist LJ05'!F20 -> 3511361.3
C9: =C6/12 -> 3504617.8 | E9: =C9/E6 -> 81.50274 | H9: Subgerente | P9: 08:00 as 21:00 | R9: 08:00 as 20:00 | U9: Junho | V9: ='Hist LJ05'!G20 -> 3390641.6 | X9: Hortifrut
U10: Julho | V10: ='Hist LJ05'!H20 -> 3635736 | X10: Venda Ano 2025 | Y10: =SUMIFS('Hist LJ05'!$N:$N,'Hist LJ05'!$P:$P,"Hortifruti") -> 5529932.1
H11: 1 | U11: Agosto | V11: ='Hist LJ05'!I20 -> 3635916.8 | X11: Media mês | Y11: =Y10/12 -> 460827.68
U12: Setembro | V12: ='Hist LJ05'!J20 -> 3451916.6 | X12: Venda Por QL | Y12: =Y11/J35 -> 230413.84
C13: FRENTE CAIXA | E13: LOJA | H13: AÇOUGUE | J13: HORTFRUTI | L13: FRIOS | N13: PADARIA | O13: CONFEITARIA | P13: ROTISSERIA | R13: Depósito | U13: Outubro | V13: ='Hist LJ05'!K20 -> 3491968.4 | X13: Meta | Y13: 80000
C14: Encarregado | E14: Encarregado | H14: Encarregado | J14: Encarregado | L14: Encarregado | N14: Encarregado | O14: Encarregado | P14: Encarregado | R14: Encarregado | U14: Novembro | V14: ='Hist LJ05'!L20 -> 3548148.3
C15: 1 | E15: 1 | H15: 1 | J15: 1 | L15: 1 | N15: 1 | O15: 0 | P15: 0 | R15: 1 | U15: Dezenbro | V15: ='Hist LJ05'!M20 -> 4004814.2 | X15: Confeitaria
U16: Total | V16: ='Hist LJ05'!N20 -> 42055414 | X16: Venda Ano 2025 | Y16: =SUMIFS('Hist LJ05'!$N:$N,'Hist LJ05'!$P:$P,"Confeitaria") -> 530367.37
C17: Fiscal de Caixa | E17: Repositor | F17: Limpeza | H17: Desossador | J17: Repositor | L17: Atendente | N17: Atendente | O17: Confeiteira | P17: Cozinheiro | R17: Conferente | U17: Media 12 meses | V17: =V16/12 -> 3504617.8 | X17: Media mês | Y17: =Y16/12 -> 44197.281
C18: 4 | E18: 6 | F18: 2 | H18: 2 | J18: 4 | L18: 2 | N18: 5 | O18: 1 | P18: 0 | R18: 1 | U18: Media por QL | V18: =V17/43000 -> 81.50274 | X18: Venda Por QL | Y18: =Y17/O35 -> 22098.64
X19: Meta | Y19: 26000
C20: Operador Caixa | E20: Cartazista | F20: Estacionamento | H20: Açogueiro | J20: Rep Cortes | L20: Repositor | N20: Padeiro | O20: Auxiliar | P20: Auxiliar | R20: Auxiliar
C21: 18 | E21: 1 | F21: 1 | H21: 4 | J21: 1 | L21: 2 | N21: 2 | O21: 1 | P21: 0 | R21: 1 | U21: Frios / Congelados / Laticinios / Peix | X21: Padaria
U22: Venda Ano 2025 | V22: =SUMIFS('Hist LJ05'!$N:$N,'Hist LJ05'!$P:$P,"Frios") -> 5330681 | X22: Venda Ano 2025 | Y22: =SUMIFS('Hist LJ05'!$N:$N,'Hist LJ05'!$P:$P,"Padaria") -> 1785382.5
C23: Empacotador | E23: Auxiliar | F23: Entregador | H23: Balconista | N23: Auxiliar | R23: Controladoria | U23: Media mês | V23: =V22/12 -> 444223.41 | X23: Media mês | Y23: =Y22/12 -> 148781.87
C24: 2 | E24: 0 | F24: 1 | H24: 3 | N24: 2 | R24: 2 | U24: Venda Por QL | V24: =V23/L35 -> 111055.85 | X24: Venda Por QL | Y24: =Y23/N35 -> 14878.187
U25: Meta | V25: 80000 | X25: Meta | Y25: 16000
E26: Aprendiz | F26: E-Commerce | R26: Prevenção
E27: 4 | F27: 0 | R27: 1 | U27: Loja Total | X27: Rotisseria
U28: Venda Ano 2025 | V28: =SUMIFS('Hist LJ05'!$N:$N,'Hist LJ05'!$P:$P,"Loja") -> 19802402 | X28: Venda Ano 2025 | Y28: =SUMIFS('Hist LJ05'!$N:$N,'Hist LJ05'!$P:$P,"Rotisseria") -> 5290.95
E29: Gestão Pessoas | F29: Cor. Bancário | U29: Media mês | V29: =V28/12 -> 1650200.2 | X29: Media mês | Y29: =Y28/12 -> 440.9125
E30: 0 | F30: 0 | U30: Venda Por QL | V30: =V29/(E35+R35) -> 61118.526 | X30: Venda Por QL | Y30: =IFERROR(Y29/P35,0) -> 0
C31: Orçado Acima | U31: Meta | V31: 160000 | X31: Meta | Y31: 25000
C32: Total | E32: Total | H32: Total | J32: Total | L32: Total | N32: PADARIA | O32: CONFEITARIA | P32: ROTISSERIA | R32: Total
C33: =C30+C27+C24+C21+C18+C15 -> 25 | E33: =E30+E27+E24+E21+E18+E15+F30+F27+F24+F21+F18 -> 16 | H33: =H30+H27+H24+H21+H18+H15 -> 10 | J33: =J30+J27+J24+J21+J18+J15 -> 6 | L33: =L30+L27+L24+L21+L18+L15 -> 5 | N33: =N30+N27+N24+N21+N18+N15 -> 10 | O33: =O30+O27+O24+O21+O18+O15 -> 2 | P33: =P30+P27+P24+P21+P18+P15 -> 0 | R33: =R30+R27+R24+R21+R18+R15 -> 6 | U33: Frente Caixa | X33: Prod Alimentos
C34: Total | E34: Total | H34: Total | J34: Total | L34: Total | N34: PADARIA | O34: CONFEITARIA | P34: ROTISSERIA | R34: Total | U34: Venda Ano 2025 | V34: =SUMIFS('Hist LJ05'!$N:$N,'Hist LJ05'!$P:$P,"Loja") -> 19802402 | X34: Venda Ano 2025 | Y34: =Y28+Y22+Y16 -> 2321040.8
C35: 19 | E35: 22 | H35: 8 | J35: 2 | L35: 4 | N35: 10 | O35: 2 | P35: =P33/SUM($N$33:$P$33)*$O$36 -> 0 | R35: 5 | U35: Media mês | V35: =V34/12 -> 1650200.2 | X35: Media mês | Y35: =Y34/12 -> 193420.07
C36: Real Fev/26 | U36: Venda Por QL | V36: =V35/C35 -> 86852.642 | X36: Venda Por QL | Y36: =Y35/SUM(N35:P35) -> 16118.339
J37: Total | L37: Real | N37: Diferença | U37: Meta | V37: 138000 | X37: Meta | Y37: 21000
J39: =SUM(C33:R33)+H11+H7 -> 82 | L39: =SUM(A35:S35) -> 72 | N39: =L39-J39 -> -10

Sheet PLJ06
C3: Loja 06 | U3: 2025 | X3: Açougue
U4: Janeiro | V4: ='Hist LJ06'!B20 -> 3688089.7 | X4: Venda Ano 2025 | Y4: =SUMIFS('Hist LJ06'!$N:$N,'Hist LJ06'!$P:$P,"Açougue") -> 9739563.2
C5: Venda 2025 | E5: Venda R$ Funcionarios | H5: Gerente | P5: Abertura da loja | U5: Fevereiro | V5: ='Hist LJ06'!C20 -> 3750186.4 | X5: Media mês | Y5: =Y4/12 -> 811630.26
C6: =V16 -> 49244758 | E6: 43000 | U6: Março | V6: ='Hist LJ06'!D20 -> 4120868.4 | X6: Venda Por QL | Y6: =Y5/H35 -> 90181.14
H7: 1 | U7: Abril | V7: ='Hist LJ06'!E20 -> 4257513.6 | X7: Meta | Y7: 75000
C8: Media 12 mêses | E8: Proposta Quant | P8: Seg a Sab | R8: Domingos | U8: Maio | V8: ='Hist LJ06'!F20 -> 4148699.6
C9: =C6/12 -> 4103729.8 | E9: =C9/E6 -> 95.435578 | H9: Subgerente | P9: 08:00 as 21:00 | R9: 08:00 as 20:00 | U9: Junho | V9: ='Hist LJ06'!G20 -> 3975894.7 | X9: Hortifrut
U10: Julho | V10: ='Hist LJ06'!H20 -> 4210990.4 | X10: Venda Ano 2025 | Y10: =SUMIFS('Hist LJ06'!$N:$N,'Hist LJ06'!$P:$P,"Hortifruti") -> 6605936.1
H11: 1 | U11: Agosto | V11: ='Hist LJ06'!I20 -> 4228069.2 | X11: Media mês | Y11: =Y10/12 -> 550494.68
U12: Setembro | V12: ='Hist LJ06'!J20 -> 3934609.1 | X12: Venda Por QL | Y12: =Y11/J35 -> 110098.94
C13: FRENTE CAIXA | E13: LOJA | H13: AÇOUGUE | J13: HORTFRUTI | L13: FRIOS | N13: PADARIA | O13: CONFEITARIA | P13: ROTISSERIA | R13: Depósito | U13: Outubro | V13: ='Hist LJ06'!K20 -> 4116730.4 | X13: Meta | Y13: 80000
C14: Encarregado | E14: Encarregado | H14: Encarregado | J14: Encarregado | L14: Encarregado | N14: Encarregado | O14: Encarregado | P14: Encarregado | R14: Encarregado | U14: Novembro | V14: ='Hist LJ06'!L20 -> 4088787.4
C15: 1 | E15: 1 | H15: 1 | J15: 1 | L15: 1 | N15: 1 | O15: 0 | P15: 0 | R15: 0 | U15: Dezenbro | V15: ='Hist LJ06'!M20 -> 4724319.3 | X15: Confeitaria
U16: Total | V16: ='Hist LJ06'!N20 -> 49244758 | X16: Venda Ano 2025 | Y16: =SUMIFS('Hist LJ06'!$N:$N,'Hist LJ06'!$P:$P,"Confeitaria") -> 656472.21
C17: Fiscal de Caixa | E17: Repositor | F17: Limpeza | H17: Desossador | J17: Repositor | L17: Atendente | N17: Atendente | O17: Confeiteira | P17: Cozinheiro | R17: Conferente | U17: Media 12 meses | V17: =V16/12 -> 4103729.8 | X17: Media mês | Y17: =Y16/12 -> 54706.017
C18: 4 | E18: 8 | F18: 3 | H18: 2 | J18: 5 | L18: 3 | N18: 5 | O18: 1 | P18: 1 | R18: 2 | U18: Media por QL | V18: =V17/43000 -> 95.435578 | X18: Venda Por QL | Y18: =Y17/O35 -> 27353.009
X19: Meta | Y19: 26000
C20: Operador Caixa | E20: Cartazista | F20: Estacionamento | H20: Açogueiro | J20: Rep Cortes | L20: Repositor | N20: Padeiro | O20: Auxiliar | P20: Auxiliar | R20: Auxiliar
C21: 18 | E21: 1 | F21: 2 | H21: 4 | J21: 1 | L21: 2 | N21: 3 | O21: 2 | P21: 1 | R21: 1 | U21: Frios / Congelados / Laticinios / Peix | X21: Padaria
U22: Venda Ano 2025 | V22: =SUMIFS('Hist LJ06'!$N:$N,'Hist LJ06'!$P:$P,"Frios") -> 6241154.5 | X22: Venda Ano 2025 | Y22: =SUMIFS('Hist LJ06'!$N:$N,'Hist LJ06'!$P:$P,"Padaria") -> 2156970.5
C23: Empacotador | E23: Auxiliar | F23: Entregador | H23: Balconista | N23: Auxiliar | R23: Controladoria | U23: Media mês | V23: =V22/12 -> 520096.21 | X23: Media mês | Y23: =Y22/12 -> 179747.54
C24: 2 | E24: 0 | F24: 2 | H24: 4 | N24: 2 | R24: 2 | U24: Venda Por QL | V24: =V23/L35 -> 104019.24 | X24: Venda Por QL | Y24: =Y23/N35 -> 14978.962
U25: Meta | V25: 80000 | X25: Meta | Y25: 16000
E26: Aprendiz | F26: E-Commerce | R26: Prevenção
E27: 5 | F27: 0 | R27: 1 | U27: Loja Total | X27: Rotisseria
U28: Venda Ano 2025 | V28: =SUMIFS('Hist LJ06'!$N:$N,'Hist LJ06'!$P:$P,"Loja") -> 23299394 | X28: Venda Ano 2025 | Y28: =SUMIFS('Hist LJ06'!$N:$N,'Hist LJ06'!$P:$P,"Rotisseria") -> 545267.73
E29: Gestão Pessoas | F29: Cor. Bancário | U29: Media mês | V29: =V28/12 -> 1941616.1 | X29: Media mês | Y29: =Y28/12 -> 45438.978
E30: 0 | F30: 0 | U30: Venda Por QL | V30: =V29/(E35+R35) -> 71911.709 | X30: Venda Por QL | Y30: =IFERROR(Y29/P35,0) -> 22719.489
C31: Orçado Acima | U31: Meta | V31: 160000 | X31: Meta | Y31: 25000
C32: Total | E32: Total | H32: Total | J32: Total | L32: Total | N32: PADARIA | O32: CONFEITARIA | P32: ROTISSERIA | R32: Total
C33: =C30+C27+C24+C21+C18+C15 -> 25 | E33: =E30+E27+E24+E21+E18+E15+F30+F27+F24+F21+F18 -> 22 | H33: =H30+H27+H24+H21+H18+H15 -> 11 | J33: =J30+J27+J24+J21+J18+J15 -> 7 | L33: =L30+L27+L24+L21+L18+L15 -> 6 | N33: =N30+N27+N24+N21+N18+N15 -> 11 | O33: =O30+O27+O24+O21+O18+O15 -> 3 | P33: =P30+P27+P24+P21+P18+P15 -> 2 | R33: =R30+R27+R24+R21+R18+R15 -> 6 | U33: Frente Caixa | X33: Prod Alimentos
C34: Total | E34: Total | H34: Total | J34: Total | L34: Total | N34: PADARIA | O34: CONFEITARIA | P34: ROTISSERIA | R34: Total | U34: Venda Ano 2025 | V34: =SUMIFS('Hist LJ06'!$N:$N,'Hist LJ06'!$P:$P,"Loja") -> 23299394 | X34: Venda Ano 2025 | Y34: =Y28+Y22+Y16 -> 3358710.5
C35: 23 | E35: 23 | H35: 9 | J35: 5 | L35: 5 | N35: 12 | O35: 2 | P35: 2 | R35: 4 | U35: Media mês | V35: =V34/12 -> 1941616.1 | X35: Media mês | Y35: =Y34/12 -> 279892.54
C36: Real Fev/26 | U36: Venda Por QL | V36: =V35/C35 -> 84418.093 | X36: Venda Por QL | Y36: =Y35/SUM(N35:P35) -> 17493.284
J37: Total | L37: Real | N37: Diferença | U37: Meta | V37: 138000 | X37: Meta | Y37: 21000
J39: =SUM(C33:R33)+H11+H7 -> 95 | L39: =SUM(A35:S35) -> 85 | N39: =L39-J39 -> -10

Sheet PLJ07
C3: Loja 07 | U3: 2025 | X3: Açougue
U4: Janeiro | V4: ='Hist LJ07'!B20 -> 3821531.6 | X4: Venda Ano 2025 | Y4: =SUMIFS('Hist LJ07'!$N:$N,'Hist LJ07'!$P:$P,"Açougue") -> 8011649.5
C5: Venda 2025 | E5: Venda R$ Funcionarios | H5: Gerente | P5: Abertura da loja | U5: Fevereiro | V5: ='Hist LJ07'!C20 -> 3629668.5 | X5: Media mês | Y5: =Y4/12 -> 667637.46
C6: =V16 -> 48793096 | E6: 43000 | U6: Março | V6: ='Hist LJ07'!D20 -> 4145407.5 | X6: Venda Por QL | Y6: =Y5/H35 -> 95376.78
H7: 1 | U7: Abril | V7: ='Hist LJ07'!E20 -> 4341610.6 | X7: Meta | Y7: 75000
C8: Media 12 mêses | E8: Proposta Quant | P8: Seg a Sab | R8: Domingos | U8: Maio | V8: ='Hist LJ07'!F20 -> 4016592.6
C9: =C6/12 -> 4066091.4 | E9: =C9/E6 -> 94.560264 | H9: Subgerente | P9: 08:00 as 21:00 | R9: 08:00 as 20:00 | U9: Junho | V9: ='Hist LJ07'!G20 -> 3792851.8 | X9: Hortifrut
U10: Julho | V10: ='Hist LJ07'!H20 -> 4114301.7 | X10: Venda Ano 2025 | Y10: =SUMIFS('Hist LJ07'!$N:$N,'Hist LJ07'!$P:$P,"Hortifruti") -> 5758169.4
H11: 1 | U11: Agosto | V11: ='Hist LJ07'!I20 -> 4102324.9 | X11: Media mês | Y11: =Y10/12 -> 479847.45
U12: Setembro | V12: ='Hist LJ07'!J20 -> 3896949.4 | X12: Venda Por QL | Y12: =Y11/J35 -> 79974.574
C13: FRENTE CAIXA | E13: LOJA | H13: AÇOUGUE | J13: HORTFRUTI | L13: FRIOS | N13: PADARIA | O13: CONFEITARIA | P13: ROTISSERIA | R13: Depósito | U13: Outubro | V13: ='Hist LJ07'!K20 -> 3922833.8 | X13: Meta | Y13: 80000
C14: Encarregado | E14: Encarregado | H14: Encarregado | J14: Encarregado | L14: Encarregado | N14: Encarregado | O14: Encarregado | P14: Encarregado | R14: Encarregado | U14: Novembro | V14: ='Hist LJ07'!L20 -> 4199361.4
C15: 1 | E15: 1 | H15: 1 | J15: 1 | L15: 1 | N15: 1 | O15: 0 | P15: 0 | R15: 1 | U15: Dezenbro | V15: ='Hist LJ07'!M20 -> 4809662.7 | X15: Confeitaria
U16: Total | V16: ='Hist LJ07'!N20 -> 48793096 | X16: Venda Ano 2025 | Y16: =SUMIFS('Hist LJ07'!$N:$N,'Hist LJ07'!$P:$P,"Confeitaria") -> 612869.45
C17: Fiscal de Caixa | E17: Repositor | F17: Limpeza | H17: Desossador | J17: Repositor | L17: Atendente | N17: Atendente | O17: Confeiteira | P17: Cozinheiro | R17: Conferente | U17: Media 12 meses | V17: =V16/12 -> 4066091.4 | X17: Media mês | Y17: =Y16/12 -> 51072.454
C18: 4 | E18: 9 | F18: 3 | H18: 2 | J18: 4 | L18: 3 | N18: 4 | O18: 1 | P18: 1 | R18: 1 | U18: Media por QL | V18: =V17/43000 -> 94.560264 | X18: Venda Por QL | Y18: =Y17/O35 -> 25536.227
X19: Meta | Y19: 26000
C20: Operador Caixa | E20: Cartazista | F20: Estacionamento | H20: Açogueiro | J20: Rep Cortes | L20: Repositor | N20: Padeiro | O20: Auxiliar | P20: Auxiliar | R20: Auxiliar
C21: 20 | E21: 1 | F21: 1 | H21: 4 | J21: 1 | L21: 2 | N21: 2 | O21: 1 | P21: 1 | R21: 2 | U21: Frios / Congelados / Laticinios / Peix | X21: Padaria
U22: Venda Ano 2025 | V22: =SUMIFS('Hist LJ07'!$N:$N,'Hist LJ07'!$P:$P,"Frios") -> 5677925.2 | X22: Venda Ano 2025 | Y22: =SUMIFS('Hist LJ07'!$N:$N,'Hist LJ07'!$P:$P,"Padaria") -> 1235218
C23: Empacotador | E23: Auxiliar | F23: Entregador | H23: Balconista | N23: Auxiliar | R23: Controladoria | U23: Media mês | V23: =V22/12 -> 473160.43 | X23: Media mês | Y23: =Y22/12 -> 102934.84
C24: 4 | E24: 0 | F24: 4 | H24: 3 | N24: 1 | R24: 2 | U24: Venda Por QL | V24: =V23/L35 -> 157720.14 | X24: Venda Por QL | Y24: =Y23/N35 -> 9357.7123
U25: Meta | V25: 80000 | X25: Meta | Y25: 16000
E26: Aprendiz | F26: E-Commerce | R26: Prevenção
E27: 2 | F27: 2 | R27: 1 | U27: Loja Total | X27: Rotisseria
U28: Venda Ano 2025 | V28: =SUMIFS('Hist LJ07'!$N:$N,'Hist LJ07'!$P:$P,"Loja") -> 27119395 | X28: Venda Ano 2025 | Y28: =SUMIFS('Hist LJ07'!$N:$N,'Hist LJ07'!$P:$P,"Rotisseria") -> 377870.25
E29: Gestão Pessoas | F29: Cor. Bancário | U29: Media mês | V29: =V28/12 -> 2259949.6 | X29: Media mês | Y29: =Y28/12 -> 31489.187
E30: 0 | F30: 0 | U30: Venda Por QL | V30: =V29/(E35+R35) -> 77929.295 | X30: Venda Por QL | Y30: =IFERROR(Y29/P35,0) -> 15744.594
C31: Orçado Acima | U31: Meta | V31: 160000 | X31: Meta | Y31: 25000
C32: Total | E32: Total | H32: Total | J32: Total | L32: Total | N32: PADARIA | O32: CONFEITARIA | P32: ROTISSERIA | R32: Total
C33: =C30+C27+C24+C21+C18+C15 -> 29 | E33: =E30+E27+E24+E21+E18+E15+F30+F27+F24+F21+F18 -> 23 | H33: =H30+H27+H24+H21+H18+H15 -> 10 | J33: =J30+J27+J24+J21+J18+J15 -> 6 | L33: =L30+L27+L24+L21+L18+L15 -> 6 | N33: =N30+N27+N24+N21+N18+N15 -> 8 | O33: =O30+O27+O24+O21+O18+O15 -> 2 | P33: =P30+P27+P24+P21+P18+P15 -> 2 | R33: =R30+R27+R24+R21+R18+R15 -> 7 | U33: Frente Caixa | X33: Prod Alimentos
C34: Total | E34: Total | H34: Total | J34: Total | L34: Total | N34: PADARIA | O34: CONFEITARIA | P34: ROTISSERIA | R34: Total | U34: Venda Ano 2025 | V34: =SUMIFS('Hist LJ07'!$N:$N,'Hist LJ07'!$P:$P,"Loja") -> 27119395 | X34: Venda Ano 2025 | Y34: =Y28+Y22+Y16 -> 2225957.7
C35: 32 | E35: 25 | H35: 7 | J35: 6 | L35: 3 | N35: 11 | O35: 2 | P35: 2 | R35: 4 | U35: Media mês | V35: =V34/12 -> 2259949.6 | X35: Media mês | Y35: =Y34/12 -> 185496.48
C36: Real Fev/26 | U36: Venda Por QL | V36: =V35/C35 -> 70623.423 | X36: Venda Por QL | Y36: =Y35/SUM(N35:P35) -> 12366.432
J37: Total | L37: Real | N37: Diferença | U37: Meta | V37: 138000 | X37: Meta | Y37: 21000
J39: =SUM(C33:R33)+H11+H7 -> 95 | L39: =SUM(C35:R35) -> 92 | N39: =L39-J39 -> -3

Sheet PLJ08
C3: Loja 08 | U3: 2025 | X3: Açougue
U4: Janeiro | V4: ='Hist LJ08'!B20 -> 3219511.4 | X4: Venda Ano 2025 | Y4: =SUMIFS('Hist LJ08'!$N:$N,'Hist LJ08'!$P:$P,"Açougue") -> 5763222.3
C5: Venda 2025 | E5: Venda R$ Funcionarios | H5: Gerente | P5: Abertura da loja | U5: Fevereiro | V5: ='Hist LJ08'!C20 -> 3101720.3 | X5: Media mês | Y5: =Y4/12 -> 480268.53
C6: =V16 -> 40395067 | E6: 43000 | U6: Março | V6: ='Hist LJ08'!D20 -> 3370344.1 | X6: Venda Por QL | Y6: =Y5/H35 -> 53363.17
H7: 1 | U7: Abril | V7: ='Hist LJ08'!E20 -> 3379026.8 | X7: Meta | Y7: 75000
C8: Media 12 mêses | E8: Proposta Quant | P8: Seg a Sab | R8: Domingos | U8: Maio | V8: ='Hist LJ08'!F20 -> 3349745.2
C9: =C6/12 -> 3366255.5 | E9: =C9/E6 -> 78.285013 | H9: Subgerente | P9: 08:00 as 21:00 | R9: 08:00 as 20:00 | U9: Junho | V9: ='Hist LJ08'!G20 -> 3073146 | X9: Hortifrut
U10: Julho | V10: ='Hist LJ08'!H20 -> 3277172.2 | X10: Venda Ano 2025 | Y10: =SUMIFS('Hist LJ08'!$N:$N,'Hist LJ08'!$P:$P,"Hortifruti") -> 4834607.6
H11: 1 | U11: Agosto | V11: ='Hist LJ08'!I20 -> 3265256.8 | X11: Media mês | Y11: =Y10/12 -> 402883.97
U12: Setembro | V12: ='Hist LJ08'!J20 -> 3058804 | X12: Venda Por QL | Y12: =Y11/J35 -> 80576.793
C13: FRENTE CAIXA | E13: LOJA | H13: AÇOUGUE | J13: HORTFRUTI | L13: FRIOS | N13: PADARIA | O13: CONFEITARIA | P13: ROTISSERIA | R13: Depósito | U13: Outubro | V13: ='Hist LJ08'!K20 -> 3373792.9 | X13: Meta | Y13: 80000
C14: Encarregado | E14: Encarregado | H14: Encarregado | J14: Encarregado | L14: Encarregado | N14: Encarregado | O14: Encarregado | P14: Encarregado | R14: Encarregado | U14: Novembro | V14: ='Hist LJ08'!L20 -> 3601251.9
C15: 1 | E15: 1 | H15: 1 | J15: 1 | L15: 1 | N15: 1 | O15: 0 | P15: 0 | R15: 1 | U15: Dezenbro | V15: ='Hist LJ08'!M20 -> 4325295.1 | X15: Confeitaria
U16: Total | V16: ='Hist LJ08'!N20 -> 40395067 | X16: Venda Ano 2025 | Y16: =SUMIFS('Hist LJ08'!$N:$N,'Hist LJ08'!$P:$P,"Confeitaria") -> 608704.17
C17: Fiscal de Caixa | E17: Repositor | F17: Limpeza | H17: Desossador | J17: Repositor | L17: Atendente | N17: Atendente | O17: Confeiteira | P17: Cozinheiro | R17: Conferente | U17: Media 12 meses | V17: =V16/12 -> 3366255.5 | X17: Media mês | Y17: =Y16/12 -> 50725.347
C18: 3 | E18: 6 | F18: 3 | H18: 2 | J18: 4 | L18: 2 | N18: 5 | O18: 1 | P18: 1 | R18: 1 | U18: Media por QL | V18: =V17/43000 -> 78.285013 | X18: Venda Por QL | Y18: =Y17/O35 -> 25362.674
X19: Meta | Y19: 26000
C20: Operador Caixa | E20: Cartazista | F20: Estacionamento | H20: Açogueiro | J20: Rep Cortes | L20: Repositor | N20: Padeiro | O20: Auxiliar | P20: Auxiliar | R20: Auxiliar
C21: 15 | E21: 1 | F21: 2 | H21: 3 | J21: 1 | L21: 2 | N21: 3 | O21: 1 | P21: 1 | R21: 1 | U21: Frios / Congelados / Laticinios / Peix | X21: Padaria
U22: Venda Ano 2025 | V22: =SUMIFS('Hist LJ08'!$N:$N,'Hist LJ08'!$P:$P,"Frios") -> 5713222.6 | X22: Venda Ano 2025 | Y22: =SUMIFS('Hist LJ08'!$N:$N,'Hist LJ08'!$P:$P,"Padaria") -> 1850270.9
C23: Empacotador | E23: Auxiliar | F23: Entregador | H23: Balconista | N23: Auxiliar | R23: Controladoria | U23: Media mês | V23: =V22/12 -> 476101.89 | X23: Media mês | Y23: =Y22/12 -> 154189.24
C24: 0 | E24: 0 | F24: 1 | H24: 2 | N24: 1 | R24: 2 | U24: Venda Por QL | V24: =V23/L35 -> 68014.555 | X24: Venda Por QL | Y24: =Y23/N35 -> 11860.711
U25: Meta | V25: 80000 | X25: Meta | Y25: 16000
E26: Aprendiz | F26: E-Commerce | R26: Prevenção
E27: 2 | F27: 1 | R27: 1 | U27: Loja Total | X27: Rotisseria
U28: Venda Ano 2025 | V28: =SUMIFS('Hist LJ08'!$N:$N,'Hist LJ08'!$P:$P,"Loja") -> 20800045 | X28: Venda Ano 2025 | Y28: =SUMIFS('Hist LJ08'!$N:$N,'Hist LJ08'!$P:$P,"Rotisseria") -> 824993.41
E29: Gestão Pessoas | F29: Cor. Bancário | U29: Media mês | V29: =V28/12 -> 1733337.1 | X29: Media mês | Y29: =Y28/12 -> 68749.451
E30: 1 | F30: 0 | U30: Venda Por QL | V30: =V29/(E35+R35) -> 86666.856 | X30: Venda Por QL | Y30: =IFERROR(Y29/P35,0) -> 34374.725
C31: Orçado Acima | U31: Meta | V31: 160000 | X31: Meta | Y31: 25000
C32: Total | E32: Total | H32: Total | J32: Total | L32: Total | N32: PADARIA | O32: CONFEITARIA | P32: ROTISSERIA | R32: Total
C33: =C30+C27+C24+C21+C18+C15 -> 19 | E33: =E30+E27+E24+E21+E18+E15+F30+F27+F24+F21+F18 -> 18 | H33: =H30+H27+H24+H21+H18+H15 -> 8 | J33: =J30+J27+J24+J21+J18+J15 -> 6 | L33: =L30+L27+L24+L21+L18+L15 -> 5 | N33: =N30+N27+N24+N21+N18+N15 -> 10 | O33: =O30+O27+O24+O21+O18+O15 -> 2 | P33: =P30+P27+P24+P21+P18+P15 -> 2 | R33: =R27+R30+R24+R21+R18+R15 -> 6 | U33: Frente Caixa | X33: Prod Alimentos
C34: Total | E34: Total | H34: Total | J34: Total | L34: Total | N34: PADARIA | O34: CONFEITARIA | P34: ROTISSERIA | R34: Total | U34: Venda Ano 2025 | V34: =SUMIFS('Hist LJ08'!$N:$N,'Hist LJ08'!$P:$P,"Loja") -> 20800045 | X34: Venda Ano 2025 | Y34: =Y28+Y22+Y16 -> 3283968.5
C35: 31 | E35: 16 | H35: 9 | J35: 5 | L35: 7 | N35: 13 | O35: 2 | P35: 2 | R35: 4 | U35: Media mês | V35: =V34/12 -> 1733337.1 | X35: Media mês | Y35: =Y34/12 -> 273664.04
C36: Real Fev/26 | U36: Venda Por QL | V36: =V35/C35 -> 55914.101 | X36: Venda Por QL | Y36: =Y35/SUM(N35:P35) -> 16097.885
J37: Total | L37: Real | N37: Diferença | U37: Meta | V37: 138000 | X37: Meta | Y37: 21000
J39: =SUM(C33:R33)+H11+H7 -> 78 | L39: =SUM(C35:R35) -> 89 | N39: =L39-J39 -> 11

Sheet PLJTT
C3: Lojas TT | U3: 2025 | X3: Açougue
U4: Janeiro | V4: ='Hist LJTT'!B20 -> 26463387 | X4: Venda Ano 2025 | Y4: =SUMIFS('Hist LJTT'!$N:$N,'Hist LJTT'!$P:$P,"Açougue") -> 61145643
C5: Venda 2025 | E5: Venda R$ Funcionarios | H5: Gerente | P5: Abertura da loja | U5: Fevereiro | V5: ='Hist LJTT'!C20 -> 25496698 | X5: Media mês | Y5: =Y4/12 -> 5095470.3
C6: =V16 -> 3.3984706e+08 | E6: 43000 | U6: Março | V6: ='Hist LJTT'!D20 -> 28607644 | X6: Venda Por QL | Y6: =Y5/H35 -> 78391.85
H7: 8 | U7: Abril | V7: ='Hist LJTT'!E20 -> 29096926 | X7: Meta | Y7: 75000
C8: Media 12 mêses | E8: Proposta Quant | P8: Seg a Sab | R8: Domingos | U8: Maio | V8: ='Hist LJTT'!F20 -> 28598246
C9: =C6/12 -> 28320588 | E9: ='PLJ01'!E9+'PLJ02'!E9+'PLJ03'!E9+'PLJ04'!E9+'PLJ05'!E9+'PLJ06'!E9+'PLJ07'!E9+'PLJ08'!E9 -> 658.61832 | H9: Subgerente | P9: 08:00 as 21:00 | R9: 08:00 as 20:00 | U9: Junho | V9: ='Hist LJTT'!G20 -> 27142168 | X9: Hortifrut
U10: Julho | V10: ='Hist LJTT'!H20 -> 28623444 | X10: Venda Ano 2025 | Y10: =SUMIFS('Hist LJTT'!$N:$N,'Hist LJTT'!$P:$P,"Hortifruti") -> 44203373
H11: 9 | U11: Agosto | V11: ='Hist LJTT'!I20 -> 28673916 | X11: Media mês | Y11: =Y10/12 -> 3683614.4
U12: Setembro | V12: ='Hist LJTT'!J20 -> 27093248 | X12: Venda Por QL | Y12: =Y11/J35 -> 92090.36
C13: FRENTE CAIXA | E13: LOJA | H13: AÇOUGUE | J13: HORTFRUTI | L13: FRIOS | N13: PADARIA | O13: CONFEITARIA | P13: ROTISSERIA | R13: Depósito | U13: Outubro | V13: ='Hist LJTT'!K20 -> 28065647 | X13: Meta | Y13: 80000
C14: Encarregado | E14: Encarregado | H14: Encarregado | J14: Encarregado | L14: Encarregado | N14: Encarregado | O14: Encarregado | P14: Encarregado | R14: Encarregado | U14: Novembro | V14: ='Hist LJTT'!L20 -> 28699918
C15: ='PLJ01'!C15+'PLJ02'!C15+'PLJ03'!C15+'PLJ04'!C15+'PLJ05'!C15+'PLJ06'!C15+'PLJ07'!C15+'PLJ08'!C15 -> 8 | E15: ='PLJ01'!E15+'PLJ02'!E15+'PLJ03'!E15+'PLJ04'!E15+'PLJ05'!E15+'PLJ06'!E15+'PLJ07'!E15+'PLJ08'!E15 -> 8 | F15: ='PLJ01'!F15+'PLJ02'!F15+'PLJ03'!F15+'PLJ04'!F15+'PLJ05'!F15+'PLJ06'!F15+'PLJ07'!F15+'PLJ08'!F15 -> 0 | H15: ='PLJ01'!H15+'PLJ02'!H15+'PLJ03'!H15+'PLJ04'!H15+'PLJ05'!H15+'PLJ06'!H15+'PLJ07'!H15+'PLJ08'!H15 -> 8 | J15: ='PLJ01'!J15+'PLJ02'!J15+'PLJ03'!J15+'PLJ04'!J15+'PLJ05'!J15+'PLJ06'!J15+'PLJ07'!J15+'PLJ08'!J15 -> 8 | L15: ='PLJ01'!L15+'PLJ02'!L15+'PLJ03'!L15+'PLJ04'!L15+'PLJ05'!L15+'PLJ06'!L15+'PLJ07'!L15+'PLJ08'!L15 -> 7 | N15: ='PLJ01'!N15+'PLJ02'!N15+'PLJ03'!N15+'PLJ04'!N15+'PLJ05'!N15+'PLJ06'!N15+'PLJ07'!N15+'PLJ08'!N15 -> 7 | O15: ='PLJ01'!O15+'PLJ02'!O15+'PLJ03'!O15+'PLJ04'!O15+'PLJ05'!O15+'PLJ06'!O15+'PLJ07'!O15+'PLJ08'!O15 -> 0 | P15: ='PLJ01'!P15+'PLJ02'!P15+'PLJ03'!P15+'PLJ04'!P15+'PLJ05'!P15+'PLJ06'!P15+'PLJ07'!P15+'PLJ08'!P15 -> 0 | R15: ='PLJ01'!R15+'PLJ02'!R15+'PLJ03'!R15+'PLJ04'!R15+'PLJ05'!R15+'PLJ06'!R15+'PLJ07'!R15+'PLJ08'!R15 -> 6 | U15: Dezenbro | V15: ='Hist LJTT'!M20 -> 33285814 | X15: Confeitaria
U16: Total | V16: ='Hist LJTT'!N20 -> 3.3984706e+08 | X16: Venda Ano 2025 | Y16: =SUMIFS('Hist LJTT'!$N:$N,'Hist LJTT'!$P:$P,"Confeitaria") -> 5208350
C17: Fiscal de Caixa | E17: Repositor | F17: Limpeza | H17: Desossador | J17: Repositor | L17: Atendente | N17: Atendente | O17: Confeiteira | P17: Cozinheiro | R17: Conferente | U17: Media 12 meses | V17: =V16/12 -> 28320588 | X17: Media mês | Y17: =Y16/12 -> 434029.16
C18: ='PLJ01'!C18+'PLJ02'!C18+'PLJ03'!C18+'PLJ04'!C18+'PLJ05'!C18+'PLJ06'!C18+'PLJ07'!C18+'PLJ08'!C18 -> 29 | E18: ='PLJ01'!E18+'PLJ02'!E18+'PLJ03'!E18+'PLJ04'!E18+'PLJ05'!E18+'PLJ06'!E18+'PLJ07'!E18+'PLJ08'!E18 -> 53 | F18: ='PLJ01'!F18+'PLJ02'!F18+'PLJ03'!F18+'PLJ04'!F18+'PLJ05'!F18+'PLJ06'!F18+'PLJ07'!F18+'PLJ08'!F18 -> 20 | H18: ='PLJ01'!H18+'PLJ02'!H18+'PLJ03'!H18+'PLJ04'!H18+'PLJ05'!H18+'PLJ06'!H18+'PLJ07'!H18+'PLJ08'!H18 -> 13 | J18: ='PLJ01'!J18+'PLJ02'!J18+'PLJ03'!J18+'PLJ04'!J18+'PLJ05'!J18+'PLJ06'!J18+'PLJ07'!J18+'PLJ08'!J18 -> 34 | L18: ='PLJ01'!L18+'PLJ02'!L18+'PLJ03'!L18+'PLJ04'!L18+'PLJ05'!L18+'PLJ06'!L18+'PLJ07'!L18+'PLJ08'!L18 -> 18 | N18: ='PLJ01'!N18+'PLJ02'!N18+'PLJ03'!N18+'PLJ04'!N18+'PLJ05'!N18+'PLJ06'!N18+'PLJ07'!N18+'PLJ08'!N18 -> 31 | O18: ='PLJ01'!O18+'PLJ02'!O18+'PLJ03'!O18+'PLJ04'!O18+'PLJ05'!O18+'PLJ06'!O18+'PLJ07'!O18+'PLJ08'!O18 -> 9 | P18: ='PLJ01'!P18+'PLJ02'!P18+'PLJ03'!P18+'PLJ04'!P18+'PLJ05'!P18+'PLJ06'!P18+'PLJ07'!P18+'PLJ08'!P18 -> 7 | R18: ='PLJ01'!R18+'PLJ02'!R18+'PLJ03'!R18+'PLJ04'!R18+'PLJ05'!R18+'PLJ06'!R18+'PLJ07'!R18+'PLJ08'!R18 -> 9 | U18: Media por QL | V18: =V17/43000 -> 658.61832 | X18: Venda Por QL | Y18: =Y17/O35 -> 28935.278
X19: Meta | Y19: 26000
C20: Operador Caixa | E20: Cartazista | F20: Estacionamento | H20: Açogueiro | J20: Rep Cortes | L20: Repositor | N20: Padeiro | O20: Auxiliar | P20: Auxiliar | R20: Auxiliar
C21: ='PLJ01'!C21+'PLJ02'!C21+'PLJ03'!C21+'PLJ04'!C21+'PLJ05'!C21+'PLJ06'!C21+'PLJ07'!C21+'PLJ08'!C21 -> 135 | E21: ='PLJ01'!E21+'PLJ02'!E21+'PLJ03'!E21+'PLJ04'!E21+'PLJ05'!E21+'PLJ06'!E21+'PLJ07'!E21+'PLJ08'!E21 -> 8 | F21: ='PLJ01'!F21+'PLJ02'!F21+'PLJ03'!F21+'PLJ04'!F21+'PLJ05'!F21+'PLJ06'!F21+'PLJ07'!F21+'PLJ08'!F21 -> 10 | H21: ='PLJ01'!H21+'PLJ02'!H21+'PLJ03'!H21+'PLJ04'!H21+'PLJ05'!H21+'PLJ06'!H21+'PLJ07'!H21+'PLJ08'!H21 -> 29 | J21: ='PLJ01'!J21+'PLJ02'!J21+'PLJ03'!J21+'PLJ04'!J21+'PLJ05'!J21+'PLJ06'!J21+'PLJ07'!J21+'PLJ08'!J21 -> 7 | L21: ='PLJ01'!L21+'PLJ02'!L21+'PLJ03'!L21+'PLJ04'!L21+'PLJ05'!L21+'PLJ06'!L21+'PLJ07'!L21+'PLJ08'!L21 -> 13 | N21: ='PLJ01'!N21+'PLJ02'!N21+'PLJ03'!N21+'PLJ04'!N21+'PLJ05'!N21+'PLJ06'!N21+'PLJ07'!N21+'PLJ08'!N21 -> 16 | O21: ='PLJ01'!O21+'PLJ02'!O21+'PLJ03'!O21+'PLJ04'!O21+'PLJ05'!O21+'PLJ06'!O21+'PLJ07'!O21+'PLJ08'!O21 -> 9 | P21: ='PLJ01'!P21+'PLJ02'!P21+'PLJ03'!P21+'PLJ04'!P21+'PLJ05'!P21+'PLJ06'!P21+'PLJ07'!P21+'PLJ08'!P21 -> 4 | R21: ='PLJ01'!R21+'PLJ02'!R21+'PLJ03'!R21+'PLJ04'!R21+'PLJ05'!R21+'PLJ06'!R21+'PLJ07'!R21+'PLJ08'!R21 -> 11 | U21: Frios / Congelados / Laticinios / Peix | X21: Padaria
U22: Venda Ano 2025 | V22: =SUMIFS('Hist LJTT'!$N:$N,'Hist LJTT'!$P:$P,"Frios") -> 41081408 | X22: Venda Ano 2025 | Y22: =SUMIFS('Hist LJTT'!$N:$N,'Hist LJTT'!$P:$P,"Padaria") -> 13262227
C23: Empacotador | E23: Auxiliar | F23: Entregador | H23: Balconista | N23: Auxiliar | R23: Controladoria | U23: Media mês | V23: =V22/12 -> 3423450.7 | X23: Media mês | Y23: =Y22/12 -> 1105185.6
C24: ='PLJ01'!C24+'PLJ02'!C24+'PLJ03'!C24+'PLJ04'!C24+'PLJ05'!C24+'PLJ06'!C24+'PLJ07'!C24+'PLJ08'!C24 -> 15 | E24: ='PLJ01'!E24+'PLJ02'!E24+'PLJ03'!E24+'PLJ04'!E24+'PLJ05'!E24+'PLJ06'!E24+'PLJ07'!E24+'PLJ08'!E24 -> 1 | F24: ='PLJ01'!F24+'PLJ02'!F24+'PLJ03'!F24+'PLJ04'!F24+'PLJ05'!F24+'PLJ06'!F24+'PLJ07'!F24+'PLJ08'!F24 -> 13 | H24: ='PLJ01'!H24+'PLJ02'!H24+'PLJ03'!H24+'PLJ04'!H24+'PLJ05'!H24+'PLJ06'!H24+'PLJ07'!H24+'PLJ08'!H24 -> 23 | N24: ='PLJ01'!N24+'PLJ02'!N24+'PLJ03'!N24+'PLJ04'!N24+'PLJ05'!N24+'PLJ06'!N24+'PLJ07'!N24+'PLJ08'!N24 -> 12 | R24: ='PLJ01'!R24+'PLJ02'!R24+'PLJ03'!R24+'PLJ04'!R24+'PLJ05'!R24+'PLJ06'!R24+'PLJ07'!R24+'PLJ08'!R24 -> 13 | U24: Venda Por QL | V24: =V23/L35 -> 106982.83 | X24: Venda Por QL | Y24: =Y23/N35 -> 14934.94
U25: Meta | V25: 80000 | X25: Meta | Y25: 16000
E26: Aprendiz | F26: E-Commerce | R26: Prevenção
E27: ='PLJ01'!E27+'PLJ02'!E27+'PLJ03'!E27+'PLJ04'!E27+'PLJ05'!E27+'PLJ06'!E27+'PLJ07'!E27+'PLJ08'!E27 -> 32 | F27: ='PLJ01'!F27+'PLJ02'!F27+'PLJ03'!F27+'PLJ04'!F27+'PLJ05'!F27+'PLJ06'!F27+'PLJ07'!F27+'PLJ08'!F27 -> 4 | R27: ='PLJ01'!R27+'PLJ02'!R27+'PLJ03'!R27+'PLJ04'!R27+'PLJ05'!R27+'PLJ06'!R27+'PLJ07'!R27+'PLJ08'!R27 -> 8 | U27: Loja Total | X27: Rotisseria
U28: Venda Ano 2025 | V28: =SUMIFS('Hist LJTT'!$N:$N,'Hist LJTT'!$P:$P,"Loja") -> 1.7161637e+08 | X28: Venda Ano 2025 | Y28: =SUMIFS('Hist LJTT'!$N:$N,'Hist LJTT'!$P:$P,"Rotisseria") -> 3329681.1
E29: Gestão Pessoas | F29: Cor. Bancário | U29: Media mês | V29: =V28/12 -> 14301364 | X29: Media mês | Y29: =Y28/12 -> 277473.42
E30: ='PLJ01'!E30+'PLJ02'!E30+'PLJ03'!E30+'PLJ04'!E30+'PLJ05'!E30+'PLJ06'!E30+'PLJ07'!E30+'PLJ08'!E30 -> 2 | F30: ='PLJ01'!F30+'PLJ02'!F30+'PLJ03'!F30+'PLJ04'!F30+'PLJ05'!F30+'PLJ06'!F30+'PLJ07'!F30+'PLJ08'!F30 -> 1 | U30: Venda Por QL | V30: =V29/(E35+R35) -> 72229.113 | X30: Venda Por QL | Y30: =Y29/P35 -> 18498.228
C31: Orçado Acima | U31: Meta | V31: 160000 | X31: Meta | Y31: 25000
C32: Total | E32: Total | H32: Total | J32: Total | L32: Total | N32: PADARIA | O32: CONFEITARIA | P32: ROTISSERIA | R32: Total
C33: =C30+C27+C24+C21+C18+C15 -> 187 | E33: =E30+E27+E24+E21+E18+E15+F30+F27+F24+F21+F18 -> 152 | H33: =H30+H27+H24+H21+H18+H15 -> 73 | J33: =J30+J27+J24+J21+J18+J15 -> 49 | L33: =L30+L27+L24+L21+L18+L15 -> 38 | N33: =N30+N27+N24+N21+N18+N15 -> 66 | O33: =O30+O27+O24+O21+O18+O15 -> 18 | P33: =P30+P27+P24+P21+P18+P15 -> 11 | R33: =R27+R30+R24+R21+R18+R15 -> 47 | U33: Frente Caixa | X33: Prod Alimentos
C34: Total | E34: Total | H34: Total | J34: Total | L34: Total | N34: PADARIA | O34: CONFEITARIA | P34: ROTISSERIA | R34: Total | U34: Venda Ano 2025 | V34: =SUMIFS('Hist LJTT'!$N:$N,'Hist LJTT'!$P:$P,"Loja") -> 1.7161637e+08 | X34: Venda Ano 2025 | Y34: =Y28+Y22+Y16 -> 21800258
C35: 190 | E35: 167 | H35: 65 | J35: 40 | L35: 32 | N35: 74 | O35: 15 | P35: 15 | R35: 31 | U35: Media mês | V35: =V34/12 -> 14301364 | X35: Media mês | Y35: =Y34/12 -> 1816688.2
C36: Real Fev/26 | U36: Venda Por QL | V36: =V35/C35 -> 75270.339 | X36: Venda Por QL | Y36: =Y35/SUM(N35:P35) -> 17468.155
J37: Total | L37: REAL | N37: Diferença | U37: Meta | V37: 138000 | X37: Meta | Y37: 21000
J39: =SUM(C33:R33)+H11+H7 -> 658 | L39: 629 | N39: =L39-J39 -> -29
K41: * | L41: ='PLJ01'!L39+'PLJ02'!L39+'PLJ03'!L39+'PLJ04'!L39+'PLJ05'!L39+'PLJ06'!L39+'PLJ07'!L39+'PLJ08'!L39 -> 629 | N41: Apenas Ativos e Férias

Sheet QLP 30
B5: Orçado | C5: Ativos | F5: Demitidos
B6: =SUM(C10:C375) -> 60 | C6: =SUM(E10:E352) -> 0 | D6: =C6-B6 -> -60 | F6: =COUNTIFS(D:D,"Demitido") -> 0
D8: DONO: ANALISTA | G8: DONO: SUPERVISOR | H8: DONO: GERENTE | M8: DONO: RH
A9: Titulo | B9: GERENTE | D9: Status | E9: Nomes | F9: Horário Sistema | G9: =IFERROR(IF(VLOOKUP($A9,#REF!,7,0)="","",VLOOKUP($A9,#REF!,7,0)),"") | H9: =IFERROR(IF(VLOOKUP($A9,#REF!,8,0)="","",VLOOKUP($A9,#REF!,8,0)),"") | I9: =IFERROR(IF(VLOOKUP($A9,#REF!,9,0)="","",VLOOKUP($A9,#REF!,9,0)),"") | J9: =IFERROR(IF(VLOOKUP($A9,#REF!,10,0)="","",VLOOKUP($A9,#REF!,10,0)),"") | K9: =IFERROR(IF(VLOOKUP($A9,#REF!,11,0)="","",VLOOKUP($A9,#REF!,11,0)),"") | L9: =IFERROR(IF(VLOOKUP($A9,#REF!,12,0)="","",VLOOKUP($A9,#REF!,12,0)),"") | M9: =IFERROR(IF(VLOOKUP($A9,#REF!,13,0)="","",VLOOKUP($A9,#REF!,13,0)),"") | N9: =IFERROR(IF(VLOOKUP($A9,#REF!,14,0)="","",VLOOKUP($A9,#REF!,14,0)),"") | O9: =IFERROR(IF(VLOOKUP($A9,#REF!,15,0)="","",VLOOKUP($A9,#REF!,15,0)),"")
A10: 1.30_DEPOSITO_GERENTE | D10: =IFERROR(VLOOKUP($A10,Banco!$A:$D,7,0),"") | E10: =IFERROR(VLOOKUP($A10,Banco!$A:$G,10,0),"-") -> - | F10: =IFERROR(RIGHT(VLOOKUP($E10,Banco!$G:$I,3,0),24),"") | G10: =IFERROR(IF(VLOOKUP($A10,#REF!,7,0)="","",VLOOKUP($A10,#REF!,7,0)),"") | H10: =IFERROR(IF(VLOOKUP($A10,#REF!,8,0)="","",VLOOKUP($A10,#REF!,8,0)),"") | I10: =IFERROR(IF(VLOOKUP($A10,#REF!,9,0)="","",VLOOKUP($A10,#REF!,9,0)),"") | J10: =IFERROR(IF(VLOOKUP($A10,#REF!,10,0)="","",VLOOKUP($A10,#REF!,10,0)),"") | K10: =IFERROR(IF(VLOOKUP($A10,#REF!,11,0)="","",VLOOKUP($A10,#REF!,11,0)),"") | L10: =IFERROR(IF(VLOOKUP($A10,#REF!,12,0)="","",VLOOKUP($A10,#REF!,12,0)),"") | M10: =IFERROR(IF(VLOOKUP($A10,#REF!,13,0)="","",VLOOKUP($A10,#REF!,13,0)),"") | N10: =IFERROR(IF(VLOOKUP($A10,#REF!,14,0)="","",VLOOKUP($A10,#REF!,14,0)),"") | O10: =IFERROR(IF(VLOOKUP($A10,#REF!,15,0)="","",VLOOKUP($A10,#REF!,15,0)),"")
A11: 2.30_DEPOSITO_GERENTE | D11: =IFERROR(VLOOKUP($A11,Banco!$A:$D,7,0),"") | E11: =IFERROR(VLOOKUP($A11,Banco!$A:$G,10,0),"-") -> - | F11: =IFERROR(RIGHT(VLOOKUP($E11,Banco!$G:$I,3,0),24),"") | G11: =IFERROR(IF(VLOOKUP($A11,#REF!,7,0)="","",VLOOKUP($A11,#REF!,7,0)),"") | H11: =IFERROR(IF(VLOOKUP($A11,#REF!,8,0)="","",VLOOKUP($A11,#REF!,8,0)),"") | I11: =IFERROR(IF(VLOOKUP($A11,#REF!,9,0)="","",VLOOKUP($A11,#REF!,9,0)),"") | J11: =IFERROR(IF(VLOOKUP($A11,#REF!,10,0)="","",VLOOKUP($A11,#REF!,10,0)),"") | K11: =IFERROR(IF(VLOOKUP($A11,#REF!,11,0)="","",VLOOKUP($A11,#REF!,11,0)),"") | L11: =IFERROR(IF(VLOOKUP($A11,#REF!,12,0)="","",VLOOKUP($A11,#REF!,12,0)),"") | M11: =IFERROR(IF(VLOOKUP($A11,#REF!,13,0)="","",VLOOKUP($A11,#REF!,13,0)),"") | N11: =IFERROR(IF(VLOOKUP($A11,#REF!,14,0)="","",VLOOKUP($A11,#REF!,14,0)),"") | O11: =IFERROR(IF(VLOOKUP($A11,#REF!,15,0)="","",VLOOKUP($A11,#REF!,15,0)),"")
A12: 3.30_DEPOSITO_GERENTE | B12: Autorizado | C12: ='PLJ30'!H7 -> 2 | D12: =IFERROR(VLOOKUP($A12,Banco!$A:$D,7,0),"") | E12: =IFERROR(VLOOKUP($A12,Banco!$A:$G,10,0),"-") -> - | F12: =IFERROR(RIGHT(VLOOKUP($E12,Banco!$G:$I,3,0),24),"") | G12: =IFERROR(IF(VLOOKUP($A12,#REF!,7,0)="","",VLOOKUP($A12,#REF!,7,0)),"") | H12: =IFERROR(IF(VLOOKUP($A12,#REF!,8,0)="","",VLOOKUP($A12,#REF!,8,0)),"") | I12: =IFERROR(IF(VLOOKUP($A12,#REF!,9,0)="","",VLOOKUP($A12,#REF!,9,0)),"") | J12: =IFERROR(IF(VLOOKUP($A12,#REF!,10,0)="","",VLOOKUP($A12,#REF!,10,0)),"") | K12: =IFERROR(IF(VLOOKUP($A12,#REF!,11,0)="","",VLOOKUP($A12,#REF!,11,0)),"") | L12: =IFERROR(IF(VLOOKUP($A12,#REF!,12,0)="","",VLOOKUP($A12,#REF!,12,0)),"") | M12: =IFERROR(IF(VLOOKUP($A12,#REF!,13,0)="","",VLOOKUP($A12,#REF!,13,0)),"") | N12: =IFERROR(IF(VLOOKUP($A12,#REF!,14,0)="","",VLOOKUP($A12,#REF!,14,0)),"") | O12: =IFERROR(IF(VLOOKUP($A12,#REF!,15,0)="","",VLOOKUP($A12,#REF!,15,0)),"")
B13: Ativos ---> | E13: =COUNTIFS(E10:E11,"<>-")-COUNTIFS(D10:D11,"Afastamento")-COUNTIFS(D10:D11,"Demitido") -> 0 | F13: =E13-C11 -> 0 | G13: =IFERROR(IF(VLOOKUP($A13,#REF!,7,0)="","",VLOOKUP($A13,#REF!,7,0)),"") | H13: =IFERROR(IF(VLOOKUP($A13,#REF!,8,0)="","",VLOOKUP($A13,#REF!,8,0)),"") | I13: =IFERROR(IF(VLOOKUP($A13,#REF!,9,0)="","",VLOOKUP($A13,#REF!,9,0)),"") | J13: =IFERROR(IF(VLOOKUP($A13,#REF!,10,0)="","",VLOOKUP($A13,#REF!,10,0)),"") | K13: =IFERROR(IF(VLOOKUP($A13,#REF!,11,0)="","",VLOOKUP($A13,#REF!,11,0)),"") | L13: =IFERROR(IF(VLOOKUP($A13,#REF!,12,0)="","",VLOOKUP($A13,#REF!,12,0)),"") | M13: =IFERROR(IF(VLOOKUP($A13,#REF!,13,0)="","",VLOOKUP($A13,#REF!,13,0)),"") | N13: =IFERROR(IF(VLOOKUP($A13,#REF!,14,0)="","",VLOOKUP($A13,#REF!,14,0)),"") | O13: =IFERROR(IF(VLOOKUP($A13,#REF!,15,0)="","",VLOOKUP($A13,#REF!,15,0)),"")
G14: =IFERROR(IF(VLOOKUP($A14,#REF!,7,0)="","",VLOOKUP($A14,#REF!,7,0)),"") | H14: =IFERROR(IF(VLOOKUP($A14,#REF!,8,0)="","",VLOOKUP($A14,#REF!,8,0)),"") | I14: =IFERROR(IF(VLOOKUP($A14,#REF!,9,0)="","",VLOOKUP($A14,#REF!,9,0)),"") | J14: =IFERROR(IF(VLOOKUP($A14,#REF!,10,0)="","",VLOOKUP($A14,#REF!,10,0)),"") | K14: =IFERROR(IF(VLOOKUP($A14,#REF!,11,0)="","",VLOOKUP($A14,#REF!,11,0)),"") | L14: =IFERROR(IF(VLOOKUP($A14,#REF!,12,0)="","",VLOOKUP($A14,#REF!,12,0)),"") | M14: =IFERROR(IF(VLOOKUP($A14,#REF!,13,0)="","",VLOOKUP($A14,#REF!,13,0)),"") | N14: =IFERROR(IF(VLOOKUP($A14,#REF!,14,0)="","",VLOOKUP($A14,#REF!,14,0)),"") | O14: =IFERROR(IF(VLOOKUP($A14,#REF!,15,0)="","",VLOOKUP($A14,#REF!,15,0)),"")
A15: Titulo | B15: ENCARREGADO | D15: Status | E15: Nomes | F15: Horário Sistema | G15: =IFERROR(IF(VLOOKUP($A15,#REF!,7,0)="","",VLOOKUP($A15,#REF!,7,0)),"") | H15: =IFERROR(IF(VLOOKUP($A15,#REF!,8,0)="","",VLOOKUP($A15,#REF!,8,0)),"") | I15: =IFERROR(IF(VLOOKUP($A15,#REF!,9,0)="","",VLOOKUP($A15,#REF!,9,0)),"") | J15: =IFERROR(IF(VLOOKUP($A15,#REF!,10,0)="","",VLOOKUP($A15,#REF!,10,0)),"") | K15: =IFERROR(IF(VLOOKUP($A15,#REF!,11,0)="","",VLOOKUP($A15,#REF!,11,0)),"") | L15: =IFERROR(IF(VLOOKUP($A15,#REF!,12,0)="","",VLOOKUP($A15,#REF!,12,0)),"") | M15: =IFERROR(IF(VLOOKUP($A15,#REF!,13,0)="","",VLOOKUP($A15,#REF!,13,0)),"") | N15: =IFERROR(IF(VLOOKUP($A15,#REF!,14,0)="","",VLOOKUP($A15,#REF!,14,0)),"") | O15: =IFERROR(IF(VLOOKUP($A15,#REF!,15,0)="","",VLOOKUP($A15,#REF!,15,0)),"")
A16: 1.30_DEPOSITO_ENCARREGADO | D16: =IFERROR(VLOOKUP($A16,Banco!$A:$D,7,0),"") | E16: =IFERROR(VLOOKUP($A16,Banco!$A:$G,10,0),"-") -> - | F16: =IFERROR(RIGHT(VLOOKUP($E16,Banco!$G:$I,3,0),24),"") | G16: =IFERROR(IF(VLOOKUP($A16,#REF!,7,0)="","",VLOOKUP($A16,#REF!,7,0)),"") | H16: =IFERROR(IF(VLOOKUP($A16,#REF!,8,0)="","",VLOOKUP($A16,#REF!,8,0)),"") | I16: =IFERROR(IF(VLOOKUP($A16,#REF!,9,0)="","",VLOOKUP($A16,#REF!,9,0)),"") | J16: =IFERROR(IF(VLOOKUP($A16,#REF!,10,0)="","",VLOOKUP($A16,#REF!,10,0)),"") | K16: =IFERROR(IF(VLOOKUP($A16,#REF!,11,0)="","",VLOOKUP($A16,#REF!,11,0)),"") | L16: =IFERROR(IF(VLOOKUP($A16,#REF!,12,0)="","",VLOOKUP($A16,#REF!,12,0)),"") | M16: =IFERROR(IF(VLOOKUP($A16,#REF!,13,0)="","",VLOOKUP($A16,#REF!,13,0)),"") | N16: =IFERROR(IF(VLOOKUP($A16,#REF!,14,0)="","",VLOOKUP($A16,#REF!,14,0)),"") | O16: =IFERROR(IF(VLOOKUP($A16,#REF!,15,0)="","",VLOOKUP($A16,#REF!,15,0)),"")
A17: 2.30_DEPOSITO_ENCARREGADO | B17: Autorizado | C17: ='PLJ30'!H11 -> 1 | D17: =IFERROR(VLOOKUP($A17,Banco!$A:$D,7,0),"") | E17: =IFERROR(VLOOKUP($A17,Banco!$A:$G,10,0),"-") -> - | F17: =IFERROR(RIGHT(VLOOKUP($E17,Banco!$G:$I,3,0),24),"") | G17: =IFERROR(IF(VLOOKUP($A17,#REF!,7,0)="","",VLOOKUP($A17,#REF!,7,0)),"") | H17: =IFERROR(IF(VLOOKUP($A17,#REF!,8,0)="","",VLOOKUP($A17,#REF!,8,0)),"") | I17: =IFERROR(IF(VLOOKUP($A17,#REF!,9,0)="","",VLOOKUP($A17,#REF!,9,0)),"") | J17: =IFERROR(IF(VLOOKUP($A17,#REF!,10,0)="","",VLOOKUP($A17,#REF!,10,0)),"") | K17: =IFERROR(IF(VLOOKUP($A17,#REF!,11,0)="","",VLOOKUP($A17,#REF!,11,0)),"") | L17: =IFERROR(IF(VLOOKUP($A17,#REF!,12,0)="","",VLOOKUP($A17,#REF!,12,0)),"") | M17: =IFERROR(IF(VLOOKUP($A17,#REF!,13,0)="","",VLOOKUP($A17,#REF!,13,0)),"") | N17: =IFERROR(IF(VLOOKUP($A17,#REF!,14,0)="","",VLOOKUP($A17,#REF!,14,0)),"") | O17: =IFERROR(IF(VLOOKUP($A17,#REF!,15,0)="","",VLOOKUP($A17,#REF!,15,0)),"")
